<?xml version="1.0" encoding="utf-8"?>

<!-- 
    This URDF uses the Denavit-Hartenberg (DH) conventions to place the reference frames of the joints.
    It uses offsets to correctly place the visual and collision meshes. The Comau SmartSix meshes are
    generated such that their reference frames' origins are always placed in a center of rotation.
    This allows to offset the visual and collision meshes by using only the displacements in the
    mechanical drawing, without the need for manual (and error-prone) adjustements.
-->

<robot  name="m20ia20m">         
    
    
    
    
    <!--************************************************BASE_LINK********************************************-->
    <link name="base_link">
        <!--link properties-->


        <visual>
            <origin xyz="0 0 0" rpy="0 0 0" />
            <geometry>
                <mesh filename="package://fanuc_description/meshes/visual/link_0.dae" />
            </geometry>
            <material name=""/>
        </visual>

        <collision>
            <origin xyz="0 0 0" rpy="0 0 0" />
            <geometry>
                <mesh filename="package://fanuc_description/meshes/collision/link_0.stl" />
            </geometry>
        </collision>

    </link>


    <!--************************************************LINK 1********************************************-->
    <link name="link1">
        <!--Link properties-->

        
        <visual>
            <origin xyz="0 0 0" rpy="0 0 3.1416" />
            <geometry>
                <mesh filename="package://fanuc_description/meshes/visual/link_1.dae" />
            </geometry>
            <material name=""/>
        </visual>

        <collision>
            <origin xyz="0 0 0" rpy="0 0 3.1416" />
            <geometry>
                <mesh filename="package://fanuc_description/meshes/collision/link_1.stl" />
            </geometry>
        </collision>

    </link>

    <joint name="joint1" type="revolute">
        <!--Joint properties-->
        <origin xyz="0 0 0" rpy="0 0 0" />
        <parent link="base_link" />
        <child link="link1" />
        <axis xyz="0 0 1" />
        <limit lower="-2.9670" upper="2.9670" effort="12"  velocity="3.40" />
    </joint>


     <!--************************************************LINK 2********************************************-->
    <link name="link2">
        <!--Link properties-->


        <visual>
            <origin xyz="0.15 0.525 0" rpy="1.5708 3.1416 0" />
            <geometry>
                <mesh filename="package://fanuc_description/meshes/visual/link_2.dae" />
            </geometry>
            <material name=""/>
        </visual>

        <collision>
            <origin xyz="0.15 0.525 0" rpy="1.5708 3.1416 0" />
            <geometry>
                <mesh filename="package://fanuc_description/meshes/collision/link_2.stl" />
            </geometry>
        </collision>

    </link>

    <joint name="joint2" type="revolute">
        <!--Joint properties-->
        <origin xyz="-0.15 0 0.525" rpy="-1.5708 0 0" />
        <parent link="link1" />
        <child link="link2" />
        <axis xyz="0 0 1" />
        <limit lower="-2.2689" upper="2.2689" effort="12" velocity="3.05" />
    </joint>


    <!--************************************************LINK 3********************************************-->
    <link name="link3">
        <!--Link properties--> 


        <visual>
            <origin xyz="1.315 -0.15 0" rpy="1.5708 3.1416 -1.5708" />
            <geometry>
                <mesh filename="package://fanuc_description/meshes/visual/link_3.dae" />
            </geometry>
             <material name=""/>
        </visual>

        <collision>
            <origin xyz="1.315 -0.15 0" rpy="1.5708 3.1416 -1.5708" />
            <geometry>
                <mesh filename="package://fanuc_description/meshes/collision/link_3.stl" />
            </geometry>
        </collision>

    </link>

    <joint name="joint3" type="revolute">
        <!--Joint properties-->
        <origin xyz="0 -0.79 0" rpy="0 0 1.5708" />
        <parent link="link2" />
        <child link="link3" />
        <axis xyz="0 0 1" />
        <limit lower="-3.9968" upper="3.9968"  effort="12" velocity="3.14" />
    </joint>


     <!--************************************************LINK 4********************************************-->
    <link name="link4">
        <!--Link properties-->


        <visual>
            <!--non 0.401 perche il datasheet non da valore corretto ma 1.5 come misurato in proporzione dul datasheet-->
            <origin xyz="1.465 0 -0.15" rpy="1.5708 -1.5708 -1.5708" />
            <geometry>
                <mesh filename="package://fanuc_description/meshes/visual/link_4.dae" />
            </geometry>
            <material name=""/>
        </visual>

        <collision>
            <origin xyz="1.465 0 -0.15" rpy="1.5708 -1.5708 -1.5708" />
            <geometry>
                <mesh filename="package://fanuc_description/meshes/collision/link_4.stl" />
            </geometry>
        </collision>

    </link>

    <joint name="joint4" type="revolute">
        <!--Joint properties-->
        <origin xyz="-0.15 0 0" rpy="-1.5708 0 0" />
        <parent link="link3" />
        <child link="link4" />
        <axis xyz="0 0 1" />
        <limit lower="-3.4906" upper="3.4906" effort="12" velocity="7.07" />
    </joint>


    <!--************************************************LINK 5********************************************-->
    <link name="link5">
        <!--Link properties-->


        <visual>
            <origin xyz="1.465 1.01 0" rpy="-1.5708 3.1416 1.5708" />
            <geometry>
                <mesh filename="package://fanuc_description/meshes/visual/link_5.dae" />
            </geometry>
            <material name=""/>
        </visual>

        <collision>
            <origin xyz="1.465 1.01 0" rpy="-1.5708 3.1416 1.5708" />
            <geometry>
                <mesh filename="package://fanuc_description/meshes/collision/link_5.stl" />
            </geometry>
        </collision>

    </link>
    
    <joint name="joint5" type="revolute">
        <!--Joint properties-->
        <origin xyz="0 0 0.86" rpy="-1.5708 0 0" />
        <parent link="link4" />
        <child link="link5" />
        <axis xyz="0 0 1" />
        <limit lower="-2.4434" upper="2.4434" effort="12" velocity="7.07" />
    </joint>


    <!--************************************************LINK 6********************************************-->
    <link name="link6">
        <!--Link properties-->


        <visual>
            <origin xyz="0 0 0.1" rpy="0 0 0" />
            <geometry>
                <mesh filename="package://fanuc_description/meshes/visual/link_6.dae" />
            </geometry>
            <material name=""/>
        </visual>

        <collision>
            <origin xyz="1.11 0 1.465" rpy="0 0 0" />
            <geometry>
                <mesh filename="package://fanuc_description/meshes/collision/link_6.stl" />
            </geometry>
        </collision>

    </link>

    <joint name="joint6" type="revolute">
        <!--Joint properties-->
        <origin xyz="0 0 0" rpy="1.5708 0 0" />
        <parent link="link5" />
        <child link="link6" />
        <axis xyz="0 0 1" />
        <limit lower="-7.8540" upper="7.8540" effort="12" velocity="10.73" />
    </joint>

    <!--************************************************FLANGE********************************************-->
    <link name="flange"/>

    <joint name="flange" type="fixed">
        <!--Joint properties-->
        <origin xyz="0 0 0.1" rpy="0 0 0" />
        <parent link="link6" />
        <child link="flange" />
    </joint>

</robot>